Workbook

Sheet 01_Raw_Data
A1: Table 2.1
A2: Overall financial literacy
A3: Average financial literacy scores (out of 100) and average components of financial literacy scores
A6: Country or Economy | B6: Financial Knowledge Score (out of 35) | C6: Financial Behaviour Score (out of 45) | D6: Financial Attitudes Score (out of 20) | E6: Financial Literacy Score (out of 100)
A7: Albania | B7: 20.15941 | C7: 22.994884 | D7: 13.245693 | E7: 56.399986
A8: Brazil | B8: 18.557501 | C8: 30.49 | D8: 10.59125 | E8: 59.638748 | G8: =IF(F8=1,E8,"")
A9: Cambodia | B9: 14.531676 | C9: 23.78723 | D9: 10.289666 | E9: 48.60857
A10: Chile | B10: 21.588284 | C10: 24.488449 | D10: 10.030941 | E10: 56.107674
A11: Costa Rica | B11: 20.705128 | C11: 25.901709 | D11: 9.8675213 | E11: 56.474358
A12: Croatia | B12: 24.528978 | C12: 26.626118 | D12: 10.877953 | E12: 62.033047
A13: Cyprus | B13: 25.44928 | C13: 20.385395 | D13: 9.9502993 | E13: 55.784973
A14: Estonia | B14: 27.471561 | C14: 27.465784 | D14: 12.26893 | E14: 67.206276
A15: Finland | B15: 24.160406 | C15: 27.940481 | D15: 12.421185 | E15: 64.508553
A16: France | B16: 23.045341 | C16: 27.240389 | D16: 11.758135 | E16: 62.043865
A17: Germany | B17: 29.822638 | C17: 33.157703 | D17: 12.98978 | E17: 75.970123
A18: Greece | B18: 22.715828 | C18: 27.95335 | D18: 10.707547 | E18: 61.376724
A19: Hong Kong (China) | B19: 31.879599 | C19: 27.493544 | D19: 10.711785 | E19: 70.08493
A20: Hungary | B20: 25.931986 | C20: 20.337309 | D20: 11.376331 | E20: 57.645626
... A47: OECD Average | B47: 23.399189 | C47: 27.711278 | D47: 11.59613 | E47: 62.705921
A49: Notes:
A50: The overall financial literacy score is computed as the sum of the scores on financial knowledge, financial behaviour and financial attitudes. The overall financial literacy score was scaled to range between 0 and 100.
A53: Table 2.2
A54: Minimum target financial literacy
A55: Percentage of adults who scored 70 points or more (out of 100) on financial literacy
A57: Country or Economy | B57: Percentage of adults reaching the minimum target score of financial literacy
A59: Albania | B59: 29.911149
A60: Brazil | B60: 29.949999
A61: Cambodia | B61: 12.490389
A62: Chile | B62: 22.937293
A63: Costa Rica | B63: 21.452992
A64: Croatia | B64: 35.585153
A65: Cyprus | B65: 16.091335
A66: Estonia | B66: 48.399082
A67: Finland | B67: 45.7587
A68: France | B68: 38.732949
A69: Germany | B69: 75.478607
A70: Greece | B70: 32.095543
... A99: OECD Average | B99: 38.898069
A102: Table 2.3
A103: Financial literacy by socio-demographic subgroups
...

Sheet 02_Knowledge_Questions
A1: Question | B1: Ireland % Correct | C1: OECD Average % | D1: Gap
A2: Definition of inflation | B2: ='01_Raw_Data'!H224 -> 97.808731 | C2: ='01_Raw_Data'!H249 -> 86.55416 | D2: =B2-C2 -> 11.25457
A3: Interest on a loan | B3: ='01_Raw_Data'!C224 -> 90.549111 | C3: ='01_Raw_Data'!C249 -> 86.894292 | D3: =B3-C3 -> 3.6548194
A4: Time value of money | B4: ='01_Raw_Data'!B224 -> 68.877959 | C4: ='01_Raw_Data'!B249 -> 69.481002 | D4: =B4-C4 -> -0.60304314
A5: Risk diversification | B5: ='01_Raw_Data'!I224 -> 62.362683 | C5: ='01_Raw_Data'!I249 -> 59.609305 | D5: =B5-C5 -> 2.7533776
A6: Simple & compound interest | B6: ='01_Raw_Data'!F224 -> 31.684276 | C6: ='01_Raw_Data'!F249 -> 31.022211 | D6: =B6-C6 -> 0.66206574

Sheet 03_Power_Query
A1: Country | B1: Metric | C1: Female | D1: Male | E1: Age_18_29 | F1: Age_30_59 | G1: Age_60_plus | H1: Less_Than_Secondary | I1: Secondary | J1: More_Than_Secondary | K1: Low_Income | L1: Medium_Income | M1: High_Income
A2: Albania | B2: Attitudes | C2: 68.635727 | D2: 63.749676 | E2: 57.786491 | F2: 66.964249 | G2: 71.121826 | H2: 69.597488 | I2: 64.879547 | J2: 64.500839 | K2: 66.0164566 | L2: 64.90532684 | M2: 68.39569855
A3: Albania | B3: Behaviour | C3: 50.090122 | D3: 52.139362 | E3: 48.349873 | F3: 52.676731 | G3: 50.128181 | H3: 48.111713 | I3: 51.595169 | J3: 53.666687 | K3: 47.75942612 | L3: 51.93126678 | M3: 55.09512329
A4: Albania | B4: Knowledge | C4: 52.584057 | D4: 62.761578 | E4: 66.332634 | F4: 59.398724 | G4: 47.621204 | H4: 43.795609 | I4: 59.606781 | J4: 70.353813 | K4: 46.57167816 | L4: 60.53119278 | M4: 70.33406067
A5: Albania | B5: Overall Literacy | C5: 54.672119 | D5: 58.179199 | E5: 56.531162 | F5: 57.886932 | G5: 53.449467 | H5: 50.898232 | I5: 57.056107 | J5: 61.674011 | K5: 50.995121 | L5: 57.5360527 | M5: 63.08886719
A6: Brazil | B6: Attitudes | C6: 52.226673 | D6: 53.757996 | E6: 58.527779 | F6: 51.965263 | G6: 49.059467 | H6: 47.483223 | I6: 54.229527 | J6: 62.001534 | K6: 51.40685654 | L6: 53.6027565 | M6: 54.54545593
A7: Brazil | B7: Behaviour | C7: 66.342026 | D7: 69.331909 | E7: 74.765434 | F7: 68.108879 | G7: 58.549084 | H7: 59.105145 | I7: 71.108719 | J7: 77.982277 | K7: 62.75693512 | L7: 69.270401 | M7: 73.94457245
A8: Brazil | B8: Knowledge | C8: 49.872089 | D8: 56.564117 | E8: 54.380951 | F8: 53.656307 | G8: 49.687935 | H8: 46.615532 | I8: 55.126232 | J8: 61.700264 | K8: 50.0092392 | L8: 53.47296906 | M8: 57.60905838
A9: Brazil | B9: Overall Literacy | C9: 57.754478 | D9: 61.748402 | E9: 64.383331 | F9: 59.821754 | G9: 53.549759 | H9: 52.409397 | I9: 62.139008 | J9: 69.087425 | K9: 56.02522659 | L9: 60.60776901 | M9: 64.34732056
A10: Cambodia | B10: Attitudes | C10: 51.03442 | D10: 51.90593 | E10: 58.938141 | F10: 49.059704 | G10: 42.276928 | H10: 47.912991 | I10: 58.085552 | J10: 66.493607 | K10: 48.73789978 | L10: 56.08390808 | M10: 55.25485611
A11: Cambodia | B11: Behaviour | C11: 52.642429 | D11: 53.101608 | E11: 54.937523 | F11: 53.575558 | G11: 44.104984 | H11: 49.487831 | I11: 56.37962 | J11: 70.038582 | K11: 49.6124382 | L11: 56.70044708 | M11: 59.576828
A12: Cambodia | B12: Knowledge | C12: 40.793949 | D12: 42.32074 | E12: 43.15823 | F12: 41.983719 | G12: 35.058819 | H12: 39.559341 | I12: 43.193211 | J12: 53.244183 | K12: 40.23737335 | L12: 42.80981445 | M12: 44.4514122
A13: Cambodia | B13: Overall Literacy | C13: 48.173859 | D13: 49.089169 | E13: 51.614895 | F13: 48.615246 | G13: 40.573215 | H13: 45.697891 | I13: 52.105564 | J13: 63.45155 | K13: 46.15625763 | L13: 51.71541595 | M13: 53.41854095
... A157: Yemen | B157: Overall Literacy | C157: 40.992931 | D157: 44.091385 | E157: 43.622879 | F157: 42.515732 | G157: 35.860771 | H157: 38.951725 | I157: 45.062019 | J157: 52.678902 | K157: 40.26330948 | L157: 44.38988876 | M157: 51.34084702

Sheet 04_Analysis
A1: Metric | B1: Ireland Score
A2: Financial Knowledge (out of 100) | B2: {=_xlfn.XLOOKUP("Ireland", TRIM('01_Raw_Data'!$A$258:$A$296), '01_Raw_Data'!$D$258:$D$296)} -> 68.970192
A3: Financial Behaviour (out of 100) | B3: {=_xlfn.XLOOKUP("Ireland", TRIM('01_Raw_Data'!$A$307:$A$345), '01_Raw_Data'!$D$307:$D$345)} -> 75.686768
A4: Financial Attitudes (out of 100) | B4: {=_xlfn.XLOOKUP("Ireland", TRIM('01_Raw_Data'!$A$356:$A$394), '01_Raw_Data'!$D$356:$D$394)} -> 57.344543
A5: Overall Literacy Score (out of 100) | B5: {=_xlfn.XLOOKUP("Ireland", TRIM('01_Raw_Data'!$A$108:$A$146), '01_Raw_Data'!$D$108:$D$146)} -> 69.667519
A6: Rank – Knowledge | B6: =RANK(B2, '01_Raw_Data'!$D$258:$D$296, 0) -> 10
A7: Rank – Behaviour | B7: =RANK(B3, '01_Raw_Data'!$D$307:$D$345, 0) -> 2
A8: Rank – Attitudes | B8: =RANK(B4, '01_Raw_Data'!$D$356:$D$394, 0) -> 13
A9: Rank – Overall | B9: =RANK(B5, '01_Raw_Data'!$D$108:$D$146, 0) -> 3
A10: Sub-score imbalance (MAX-MIN) | B10: =MAX(B2,B3,B4)-MIN(B2,B3,B4) -> 18.342224
A11: vs OECD Average | B11: {=_xlfn.IFS( '01_Raw_Data'!D123>'01_Raw_Data'!D147,"Above OECD Average", '01_Raw_Data'!D123='01_Raw_Data'!ED147,"At Average", TRUE,"Below Average" )} -> Above OECD Average
A13: Demographic Group | B13: Ireland Score | C13: OECD Average Score
A14: Female | B14: {=_xlfn.XLOOKUP("Ireland", TRIM('01_Raw_Data'!$A$107:$A$148),'01_Raw_Data'!B$107:B$148)} -> 68.006477 | C14: ='01_Raw_Data'!B$148 -> 61.463243
A15: Male | B15: {=_xlfn.XLOOKUP("Ireland", TRIM('01_Raw_Data'!$A$107:$A$148),'01_Raw_Data'!C$107:C$148)} -> 71.300621 | C15: ='01_Raw_Data'!C$148 -> 64.017488
A16: Age 18-29 | B16: {=_xlfn.XLOOKUP("Ireland", TRIM('01_Raw_Data'!$A$107:$A$148),'01_Raw_Data'!D$107:D$148)} -> 69.667519 | C16: ='01_Raw_Data'!D$148 -> 60.011015
A17: Age 30-59 | B17: {=_xlfn.XLOOKUP("Ireland", TRIM('01_Raw_Data'!$A$107:$A$148),'01_Raw_Data'!E$107:E$148)} -> 71.677818 | C17: ='01_Raw_Data'!E$148 -> 63.959994
A18: Age 60+ | B18: {=_xlfn.XLOOKUP("Ireland", TRIM('01_Raw_Data'!$A$107:$A$148),'01_Raw_Data'!F$107:F$148)} -> 66.316872 | C18: ='01_Raw_Data'!F$148 -> 61.380911
A19: Less than secondary | B19: {=_xlfn.XLOOKUP("Ireland", TRIM('01_Raw_Data'!$A$107:$A$148),'01_Raw_Data'!G$107:G$148)} -> 64.858719 | C19: ='01_Raw_Data'!G$148 -> 56.830358
A20: Secondary | B20: {=_xlfn.XLOOKUP("Ireland", TRIM('01_Raw_Data'!$A$107:$A$148),'01_Raw_Data'!H$107:H$148)} -> 74.464279 | C20: ='01_Raw_Data'!H$148 -> 64.071725
A21: More than secondary | B21: {=_xlfn.XLOOKUP("Ireland", TRIM('01_Raw_Data'!$A$107:$A$148),'01_Raw_Data'!I$107:I$148)} -> 76.827225 | C21: ='01_Raw_Data'!I$148 -> 69.653188
A22: Low income | B22: {=_xlfn.XLOOKUP("Ireland", TRIM('01_Raw_Data'!$A$107:$A$148),'01_Raw_Data'!Q$107:Q$148)} -> 64.327499 | C22: ='01_Raw_Data'!Q$148 -> 57.618927
A23: Medium income | B23: {=_xlfn.XLOOKUP("Ireland", TRIM('01_Raw_Data'!$A$107:$A$148),'01_Raw_Data'!R$107:R$148)} -> 73.637489 | C23: ='01_Raw_Data'!$R$148 -> 64.383871
A24: High income | B24: {=_xlfn.XLOOKUP("Ireland", TRIM('01_Raw_Data'!$A$107:$A$148),'01_Raw_Data'!S$107:S$148)} -> 75.536949 | C24: ='01_Raw_Data'!$S$148 -> 68.945917

Sheet 05_Clean_Table
A1: Country | B1: OECD_Member | C1: Knowledge_Out_Of_100 | D1: Behaviour_Out_Of_100 | E1: Attitudes_Out_Of_100 | F1: Overall_Score_Out_Of_100 | G1: %_Reaching_Minimum_Target_Score | H1: Overall_Rank_Out_Of_39 | I1: Score_Female | J1: Score_Male | K1: Score_18_29 | L1: Score_30_59 | M1: Score_60_and_over | N1: Score_Less_Than_Secondary | O1: Score_Secondary | P1: Score_More_Than_Secondary | Q1: Score_Low | R1: Score_Medium | S1: Score_High
A2: =_xlfn.XLOOKUP('01_Raw_Data'!$A7,'01_Raw_Data'!$A$7:$A$45, '01_Raw_Data'!$A$7:$A$45) -> Albania | B2: No | C2: =_xlfn.XLOOKUP('01_Raw_Data'!$A258, '01_Raw_Data'!$A$258:$A$296, '01_Raw_Data'!$D$258:$D$296) -> 66.332634 | D2: =_xlfn.XLOOKUP('01_Raw_Data'!$A307, '01_Raw_Data'!$A$307:$A$345,'01_Raw_Data'!$D$307:$D$345) -> 48.349873 | E2: =_xlfn.XLOOKUP('01_Raw_Data'!$A356, '01_Raw_Data'!$A$356:$A$394, '01_Raw_Data'!$D$356:$D$394) -> 57.786491 | F2: =_xlfn.XLOOKUP('01_Raw_Data'!$A108, '01_Raw_Data'!$A$108:$A$146, '01_Raw_Data'!$D$108:$D$146) -> 56.531162 | G2: =_xlfn.XLOOKUP('01_Raw_Data'!$A59,'01_Raw_Data'!$A$59:$A$97, '01_Raw_Data'!$B$59:$B$97) -> 29.911149 | H2: =RANK('01_Raw_Data'!$D108, '01_Raw_Data'!$D$108:$D$146, 0) -> 28 | I2: =_xlfn.XLOOKUP($A2,'01_Raw_Data'!$A$107:$A$148,'01_Raw_Data'!$B$107:$B$148) -> 54.672119 | J2: =_xlfn.XLOOKUP($A2,'01_Raw_Data'!$A$107:$A$148,'01_Raw_Data'!$C$107:$C$148) -> 58.179199 | K2: =_xlfn.XLOOKUP($A2,'01_Raw_Data'!$A$107:$A$148,'01_Raw_Data'!$D$107:$D$148) -> 56.531162 | L2: =_xlfn.XLOOKUP($A2,'01_Raw_Data'!$A$107:$A$148,'01_Raw_Data'!$E$107:$E$148) -> 57.886932 | M2: =_xlfn.XLOOKUP($A2,'01_Raw_Data'!$A$107:$A$148,'01_Raw_Data'!$F$107:$F$148) -> 53.449467 | N2: =_xlfn.XLOOKUP($A2,'01_Raw_Data'!$A$107:$A$148,'01_Raw_Data'!$G$107:$G$148) -> 50.898232 | O2: =_xlfn.XLOOKUP($A2,'01_Raw_Data'!$A$107:$A$148,'01_Raw_Data'!$H$107:$H$148) -> 57.056107 | P2: =_xlfn.XLOOKUP($A2,'01_Raw_Data'!$A$107:$A$148,'01_Raw_Data'!$I$107:$I$148) -> 61.674011 | Q2: =_xlfn.XLOOKUP($A2,'01_Raw_Data'!$A$107:$A$148,'01_Raw_Data'!$Q$107:$Q$148) -> 50.995121 | R2: =_xlfn.XLOOKUP($A2,'01_Raw_Data'!$A$107:$A$148,'01_Raw_Data'!$R$107:$R$148) -> 57.536053 | S2: =_xlfn.XLOOKUP($A2,'01_Raw_Data'!$A$107:$A$148,'01_Raw_Data'!$S$107:$S$148) -> 63.088867
A3: =_xlfn.XLOOKUP('01_Raw_Data'!$A8,'01_Raw_Data'!$A$7:$A$45, '01_Raw_Data'!$A$7:$A$45) -> Brazil | B3: No | C3: =_xlfn.XLOOKUP('01_Raw_Data'!$A259, '01_Raw_Data'!$A$258:$A$296, '01_Raw_Data'!$D$258:$D$296) -> 54.380951 | D3: =_xlfn.XLOOKUP('01_Raw_Data'!$A308, '01_Raw_Data'!$A$307:$A$345,'01_Raw_Data'!$D$307:$D$345) -> 74.765434 | E3: =_xlfn.XLOOKUP('01_Raw_Data'!$A357, '01_Raw_Data'!$A$356:$A$394, '01_Raw_Data'!$D$356:$D$394) -> 58.527779 | F3: =_xlfn.XLOOKUP('01_Raw_Data'!$A109, '01_Raw_Data'!$A$108:$A$146, '01_Raw_Data'!$D$108:$D$146) -> 64.383331 | G3: =_xlfn.XLOOKUP('01_Raw_Data'!$A60,'01_Raw_Data'!$A$59:$A$97, '01_Raw_Data'!$B$59:$B$97) -> 29.949999 | H3: =RANK('01_Raw_Data'!$D109, '01_Raw_Data'!$D$108:$D$146, 0) -> 10 | I3: =_xlfn.XLOOKUP($A3,'01_Raw_Data'!$A$107:$A$148,'01_Raw_Data'!$B$107:$B$148) -> 57.754478 | J3: =_xlfn.XLOOKUP($A3,'01_Raw_Data'!$A$107:$A$148,'01_Raw_Data'!$C$107:$C$148) -> 61.748402 | K3: =_xlfn.XLOOKUP($A3,'01_Raw_Data'!$A$107:$A$148,'01_Raw_Data'!$D$107:$D$148) -> 64.383331 | L3: =_xlfn.XLOOKUP($A3,'01_Raw_Data'!$A$107:$A$148,'01_Raw_Data'!$E$107:$E$148) -> 59.821754 | M3: =_xlfn.XLOOKUP($A3,'01_Raw_Data'!$A$107:$A$148,'01_Raw_Data'!$F$107:$F$148) -> 53.549759 | N3: =_xlfn.XLOOKUP($A3,'01_Raw_Data'!$A$107:$A$148,'01_Raw_Data'!$G$107:$G$148) -> 52.409397 | O3: =_xlfn.XLOOKUP($A3,'01_Raw_Data'!$A$107:$A$148,'01_Raw_Data'!$H$107:$H$148) -> 62.139008 | P3: =_xlfn.XLOOKUP($A3,'01_Raw_Data'!$A$107:$A$148,'01_Raw_Data'!$I$107:$I$148) -> 69.087425 | Q3: =_xlfn.XLOOKUP($A3,'01_Raw_Data'!$A$107:$A$148,'01_Raw_Data'!$Q$107:$Q$148) -> 56.025227 | R3: =_xlfn.XLOOKUP($A3,'01_Raw_Data'!$A$107:$A$148,'01_Raw_Data'!$R$107:$R$148) -> 60.607769 | S3: =_xlfn.XLOOKUP($A3,'01_Raw_Data'!$A$107:$A$148,'01_Raw_Data'!$S$107:$S$148) -> 64.347321
A4: =_xlfn.XLOOKUP('01_Raw_Data'!$A9,'01_Raw_Data'!$A$7:$A$45, '01_Raw_Data'!$A$7:$A$45) -> Cambodia | B4: No | C4: =_xlfn.XLOOKUP('01_Raw_Data'!$A260, '01_Raw_Data'!$A$258:$A$296, '01_Raw_Data'!$D$258:$D$296) -> 43.15823 | D4: =_xlfn.XLOOKUP('01_Raw_Data'!$A309, '01_Raw_Data'!$A$307:$A$345,'01_Raw_Data'!$D$307:$D$345) -> 54.937523 | E4: =_xlfn.XLOOKUP('01_Raw_Data'!$A358, '01_Raw_Data'!$A$356:$A$394, '01_Raw_Data'!$D$356:$D$394) -> 58.938141 | F4: =_xlfn.XLOOKUP('01_Raw_Data'!$A110, '01_Raw_Data'!$A$108:$A$146, '01_Raw_Data'!$D$108:$D$146) -> 51.614895 | G4: =_xlfn.XLOOKUP('01_Raw_Data'!$A61,'01_Raw_Data'!$A$59:$A$97, '01_Raw_Data'!$B$59:$B$97) -> 12.490389 | H4: =RANK('01_Raw_Data'!$D110, '01_Raw_Data'!$D$108:$D$146, 0) -> 36 | I4: =_xlfn.XLOOKUP($A4,'01_Raw_Data'!$A$107:$A$148,'01_Raw_Data'!$B$107:$B$148) -> 48.173859 | J4: =_xlfn.XLOOKUP($A4,'01_Raw_Data'!$A$107:$A$148,'01_Raw_Data'!$C$107:$C$148) -> 49.089169 | K4: =_xlfn.XLOOKUP($A4,'01_Raw_Data'!$A$107:$A$148,'01_Raw_Data'!$D$107:$D$148) -> 51.614895 | L4: =_xlfn.XLOOKUP($A4,'01_Raw_Data'!$A$107:$A$148,'01_Raw_Data'!$E$107:$E$148) -> 48.615246 | M4: =_xlfn.XLOOKUP($A4,'01_Raw_Data'!$A$107:$A$148,'01_Raw_Data'!$F$107:$F$148) -> 40.573215 | N4: =_xlfn.XLOOKUP($A4,'01_Raw_Data'!$A$107:$A$148,'01_Raw_Data'!$G$107:$G$148) -> 45.697891 | O4: =_xlfn.XLOOKUP($A4,'01_Raw_Data'!$A$107:$A$148,'01_Raw_Data'!$H$107:$H$148) -> 52.105564 | P4: =_xlfn.XLOOKUP($A4,'01_Raw_Data'!$A$107:$A$148,'01_Raw_Data'!$I$107:$I$148) -> 63.45155 | Q4: =_xlfn.XLOOKUP($A4,'01_Raw_Data'!$A$107:$A$148,'01_Raw_Data'!$Q$107:$Q$148) -> 46.156258 | R4: =_xlfn.XLOOKUP($A4,'01_Raw_Data'!$A$107:$A$148,'01_Raw_Data'!$R$107:$R$148) -> 51.715416 | S4: =_xlfn.XLOOKUP($A4,'01_Raw_Data'!$A$107:$A$148,'01_Raw_Data'!$S$107:$S$148) -> 53.418541
A5: =_xlfn.XLOOKUP('01_Raw_Data'!$A10,'01_Raw_Data'!$A$7:$A$45, '01_Raw_Data'!$A$7:$A$45) -> Chile | B5: Yes | C5: =_xlfn.XLOOKUP('01_Raw_Data'!$A261, '01_Raw_Data'!$A$258:$A$296, '01_Raw_Data'!$D$258:$D$296) -> 57.908165 | D5: =_xlfn.XLOOKUP('01_Raw_Data'!$A310, '01_Raw_Data'!$A$307:$A$345,'01_Raw_Data'!$D$307:$D$345) -> 45.238094 | E5: =_xlfn.XLOOKUP('01_Raw_Data'!$A359, '01_Raw_Data'!$A$356:$A$394, '01_Raw_Data'!$D$356:$D$394) -> 56.69643 | F5: =_xlfn.XLOOKUP('01_Raw_Data'!$A111, '01_Raw_Data'!$A$108:$A$146, '01_Raw_Data'!$D$108:$D$146) -> 51.964287 | G5: =_xlfn.XLOOKUP('01_Raw_Data'!$A62,'01_Raw_Data'!$A$59:$A$97, '01_Raw_Data'!$B$59:$B$97) -> 22.937293 | H5: =RANK('01_Raw_Data'!$D111, '01_Raw_Data'!$D$108:$D$146, 0) -> 34 | I5: =_xlfn.XLOOKUP($A5,'01_Raw_Data'!$A$107:$A$148,'01_Raw_Data'!$B$107:$B$148) -> 55.613773 | J5: =_xlfn.XLOOKUP($A5,'01_Raw_Data'!$A$107:$A$148,'01_Raw_Data'!$C$107:$C$148) -> 56.714153 | K5: =_xlfn.XLOOKUP($A5,'01_Raw_Data'!$A$107:$A$148,'01_Raw_Data'!$D$107:$D$148) -> 51.964287 | L5: =_xlfn.XLOOKUP($A5,'01_Raw_Data'!$A$107:$A$148,'01_Raw_Data'!$E$107:$E$148) -> 57.285713 | M5: =_xlfn.XLOOKUP($A5,'01_Raw_Data'!$A$107:$A$148,'01_Raw_Data'!$F$107:$F$148) -> 51.921181 | N5: =_xlfn.XLOOKUP($A5,'01_Raw_Data'!$A$107:$A$148,'01_Raw_Data'!$G$107:$G$148) -> 47.64706 | O5: =_xlfn.XLOOKUP($A5,'01_Raw_Data'!$A$107:$A$148,'01_Raw_Data'!$H$107:$H$148) -> 55.998474 | P5: =_xlfn.XLOOKUP($A5,'01_Raw_Data'!$A$107:$A$148,'01_Raw_Data'!$I$107:$I$148) -> 64.463028 | Q5: =_xlfn.XLOOKUP($A5,'01_Raw_Data'!$A$107:$A$148,'01_Raw_Data'!$Q$107:$Q$148) -> 51.127098 | R5: =_xlfn.XLOOKUP($A5,'01_Raw_Data'!$A$107:$A$148,'01_Raw_Data'!$R$107:$R$148) -> 56.21822 | S5: =_xlfn.XLOOKUP($A5,'01_Raw_Data'!$A$107:$A$148,'01_Raw_Data'!$S$107:$S$148) -> 65.304619
A6: =_xlfn.XLOOKUP('01_Raw_Data'!$A11,'01_Raw_Data'!$A$7:$A$45, '01_Raw_Data'!$A$7:$A$45) -> Costa Rica | B6: Yes | C6: =_xlfn.XLOOKUP('01_Raw_Data'!$A262, '01_Raw_Data'!$A$258:$A$296, '01_Raw_Data'!$D$258:$D$296) -> 58.266979 | D6: =_xlfn.XLOOKUP('01_Raw_Data'!$A311, '01_Raw_Data'!$A$307:$A$345,'01_Raw_Data'!$D$307:$D$345) -> 56.976318 | E6: =_xlfn.XLOOKUP('01_Raw_Data'!$A360, '01_Raw_Data'!$A$356:$A$394, '01_Raw_Data'!$D$356:$D$394) -> 55.532787 | F6: =_xlfn.XLOOKUP('01_Raw_Data'!$A112, '01_Raw_Data'!$A$108:$A$146, '01_Raw_Data'!$D$108:$D$146) -> 57.139343 | G6: =_xlfn.XLOOKUP('01_Raw_Data'!$A63,'01_Raw_Data'!$A$59:$A$97, '01_Raw_Data'!$B$59:$B$97) -> 21.452992 | H6: =RANK('01_Raw_Data'!$D112, '01_Raw_Data'!$D$108:$D$146, 0) -> 25 | I6: =_xlfn.XLOOKUP($A6,'01_Raw_Data'!$A$107:$A$148,'01_Raw_Data'!$B$107:$B$148) -> 55.115383 | J6: =_xlfn.XLOOKUP($A6,'01_Raw_Data'!$A$107:$A$148,'01_Raw_Data'!$C$107:$C$148) -> 57.833332 | K6: =_xlfn.XLOOKUP($A6,'01_Raw_Data'!$A$107:$A$148,'01_Raw_Data'!$D$107:$D$148) -> 57.139343 | L6: =_xlfn.XLOOKUP($A6,'01_Raw_Data'!$A$107:$A$148,'01_Raw_Data'!$E$107:$E$148) -> 56.955486 | M6: =_xlfn.XLOOKUP($A6,'01_Raw_Data'!$A$107:$A$148,'01_Raw_Data'!$F$107:$F$148) -> 54.465065 | N6: =_xlfn.XLOOKUP($A6,'01_Raw_Data'!$A$107:$A$148,'01_Raw_Data'!$G$107:$G$148) -> 51.649815 | O6: =_xlfn.XLOOKUP($A6,'01_Raw_Data'!$A$107:$A$148,'01_Raw_Data'!$H$107:$H$148) -> 57.789948 | P6: =_xlfn.XLOOKUP($A6,'01_Raw_Data'!$A$107:$A$148,'01_Raw_Data'!$I$107:$I$148) -> 65.35714 | Q6: =_xlfn.XLOOKUP($A6,'01_Raw_Data'!$A$107:$A$148,'01_Raw_Data'!$Q$107:$Q$148) -> 52.473331 | R6: =_xlfn.XLOOKUP($A6,'01_Raw_Data'!$A$107:$A$148,'01_Raw_Data'!$R$107:$R$148) -> 56.432636 | S6: =_xlfn.XLOOKUP($A6,'01_Raw_Data'!$A$107:$A$148,'01_Raw_Data'!$S$107:$S$148) -> 62.15485
A7: =_xlfn.XLOOKUP('01_Raw_Data'!$A12,'01_Raw_Data'!$A$7:$A$45, '01_Raw_Data'!$A$7:$A$45) -> Croatia | B7: Yes | C7: =_xlfn.XLOOKUP('01_Raw_Data'!$A263, '01_Raw_Data'!$A$258:$A$296, '01_Raw_Data'!$D$258:$D$296) -> 70.461189 | D7: =_xlfn.XLOOKUP('01_Raw_Data'!$A312, '01_Raw_Data'!$A$307:$A$345,'01_Raw_Data'!$D$307:$D$345) -> 57.629528 | E7: =_xlfn.XLOOKUP('01_Raw_Data'!$A361, '01_Raw_Data'!$A$356:$A$394, '01_Raw_Data'!$D$356:$D$394) -> 51.042339 | F7: =_xlfn.XLOOKUP('01_Raw_Data'!$A113, '01_Raw_Data'!$A$108:$A$146, '01_Raw_Data'!$D$108:$D$146) -> 60.803169 | G7: =_xlfn.XLOOKUP('01_Raw_Data'!$A64,'01_Raw_Data'!$A$59:$A$97, '01_Raw_Data'!$B$59:$B$97) -> 35.585153 | H7: =RANK('01_Raw_Data'!$D113, '01_Raw_Data'!$D$108:$D$146, 0) -> 13 | I7: =_xlfn.XLOOKUP($A7,'01_Raw_Data'!$A$107:$A$148,'01_Raw_Data'!$B$107:$B$148) -> 62.14529 | J7: =_xlfn.XLOOKUP($A7,'01_Raw_Data'!$A$107:$A$148,'01_Raw_Data'!$C$107:$C$148) -> 61.91433 | K7: =_xlfn.XLOOKUP($A7,'01_Raw_Data'!$A$107:$A$148,'01_Raw_Data'!$D$107:$D$148) -> 60.803169 | L7: =_xlfn.XLOOKUP($A7,'01_Raw_Data'!$A$107:$A$148,'01_Raw_Data'!$E$107:$E$148) -> 63.676968 | M7: =_xlfn.XLOOKUP($A7,'01_Raw_Data'!$A$107:$A$148,'01_Raw_Data'!$F$107:$F$148) -> 59.98315 | N7: =_xlfn.XLOOKUP($A7,'01_Raw_Data'!$A$107:$A$148,'01_Raw_Data'!$G$107:$G$148) -> 60.368797 | O7: =_xlfn.XLOOKUP($A7,'01_Raw_Data'!$A$107:$A$148,'01_Raw_Data'!$H$107:$H$148) -> 67.255562 | P7: =_xlfn.XLOOKUP($A7,'01_Raw_Data'!$A$107:$A$148,'01_Raw_Data'!$I$107:$I$148) -> 71.935806 | Q7: =_xlfn.XLOOKUP($A7,'01_Raw_Data'!$A$107:$A$148,'01_Raw_Data'!$Q$107:$Q$148) -> 57.605663 | R7: =_xlfn.XLOOKUP($A7,'01_Raw_Data'!$A$107:$A$148,'01_Raw_Data'!$R$107:$R$148) -> 65.215454 | S7: =_xlfn.XLOOKUP($A7,'01_Raw_Data'!$A$107:$A$148,'01_Raw_Data'!$S$107:$S$148) -> 65.606049
A8: =_xlfn.XLOOKUP('01_Raw_Data'!$A13,'01_Raw_Data'!$A$7:$A$45, '01_Raw_Data'!$A$7:$A$45) -> Cyprus | B8: No | C8: =_xlfn.XLOOKUP('01_Raw_Data'!$A264, '01_Raw_Data'!$A$258:$A$296, '01_Raw_Data'!$D$258:$D$296) -> 66.400551 | D8: =_xlfn.XLOOKUP('01_Raw_Data'!$A313, '01_Raw_Data'!$A$307:$A$345,'01_Raw_Data'!$D$307:$D$345) -> 45.673923 | E8: =_xlfn.XLOOKUP('01_Raw_Data'!$A362, '01_Raw_Data'!$A$356:$A$394, '01_Raw_Data'!$D$356:$D$394) -> 48.164268 | F8: =_xlfn.XLOOKUP('01_Raw_Data'!$A114, '01_Raw_Data'!$A$108:$A$146, '01_Raw_Data'!$D$108:$D$146) -> 53.426315 | G8: =_xlfn.XLOOKUP('01_Raw_Data'!$A65,'01_Raw_Data'!$A$59:$A$97, '01_Raw_Data'!$B$59:$B$97) -> 16.091335 | H8: =RANK('01_Raw_Data'!$D114, '01_Raw_Data'!$D$108:$D$146, 0) -> 33 | I8: =_xlfn.XLOOKUP($A8,'01_Raw_Data'!$A$107:$A$148,'01_Raw_Data'!$B$107:$B$148) -> 54.876698 | J8: =_xlfn.XLOOKUP($A8,'01_Raw_Data'!$A$107:$A$148,'01_Raw_Data'!$C$107:$C$148) -> 56.754211 | K8: =_xlfn.XLOOKUP($A8,'01_Raw_Data'!$A$107:$A$148,'01_Raw_Data'!$D$107:$D$148) -> 53.426315 | L8: =_xlfn.XLOOKUP($A8,'01_Raw_Data'!$A$107:$A$148,'01_Raw_Data'!$E$107:$E$148) -> 57.109875 | M8: =_xlfn.XLOOKUP($A8,'01_Raw_Data'!$A$107:$A$148,'01_Raw_Data'!$F$107:$F$148) -> 55.754375 | N8: =_xlfn.XLOOKUP($A8,'01_Raw_Data'!$A$107:$A$148,'01_Raw_Data'!$G$107:$G$148) -> 48.13295 | O8: =_xlfn.XLOOKUP($A8,'01_Raw_Data'!$A$107:$A$148,'01_Raw_Data'!$H$107:$H$148) -> 53.856155 | P8: =_xlfn.XLOOKUP($A8,'01_Raw_Data'!$A$107:$A$148,'01_Raw_Data'!$I$107:$I$148) -> 58.414936 | Q8: =_xlfn.XLOOKUP($A8,'01_Raw_Data'!$A$107:$A$148,'01_Raw_Data'!$Q$107:$Q$148) -> 51.584183 | R8: =_xlfn.XLOOKUP($A8,'01_Raw_Data'!$A$107:$A$148,'01_Raw_Data'!$R$107:$R$148) -> 55.737148 | S8: =_xlfn.XLOOKUP($A8,'01_Raw_Data'!$A$107:$A$148,'01_Raw_Data'!$S$107:$S$148) -> 57.221527
A9: =_xlfn.XLOOKUP('01_Raw_Data'!$A14,'01_Raw_Data'!$A$7:$A$45, '01_Raw_Data'!$A$7:$A$45) -> Estonia | B9: Yes | C9: =_xlfn.XLOOKUP('01_Raw_Data'!$A265, '01_Raw_Data'!$A$258:$A$296, '01_Raw_Data'!$D$258:$D$296) -> 81.16674 | D9: =_xlfn.XLOOKUP('01_Raw_Data'!$A314, '01_Raw_Data'!$A$307:$A$345,'01_Raw_Data'!$D$307:$D$345) -> 62.734463 | E9: =_xlfn.XLOOKUP('01_Raw_Data'!$A363, '01_Raw_Data'!$A$356:$A$394, '01_Raw_Data'!$D$356:$D$394) -> 61.101662 | F9: =_xlfn.XLOOKUP('01_Raw_Data'!$A115, '01_Raw_Data'!$A$108:$A$146, '01_Raw_Data'!$D$108:$D$146) -> 68.8592 | G9: =_xlfn.XLOOKUP('01_Raw_Data'!$A66,'01_Raw_Data'!$A$59:$A$97, '01_Raw_Data'!$B$59:$B$97) -> 48.399082 | H9: =RANK('01_Raw_Data'!$D115, '01_Raw_Data'!$D$108:$D$146, 0) -> 4 | I9: =_xlfn.XLOOKUP($A9,'01_Raw_Data'!$A$107:$A$148,'01_Raw_Data'!$B$107:$B$148) -> 65.823769 | J9: =_xlfn.XLOOKUP($A9,'01_Raw_Data'!$A$107:$A$148,'01_Raw_Data'!$C$107:$C$148) -> 69.116394 | K9: =_xlfn.XLOOKUP($A9,'01_Raw_Data'!$A$107:$A$148,'01_Raw_Data'!$D$107:$D$148) -> 68.8592 | L9: =_xlfn.XLOOKUP($A9,'01_Raw_Data'!$A$107:$A$148,'01_Raw_Data'!$E$107:$E$148) -> 68.112953 | M9: =_xlfn.XLOOKUP($A9,'01_Raw_Data'!$A$107:$A$148,'01_Raw_Data'!$F$107:$F$148) -> 64.454987 | N9: =_xlfn.XLOOKUP($A9,'01_Raw_Data'!$A$107:$A$148,'01_Raw_Data'!$G$107:$G$148) -> 65.445183 | O9: =_xlfn.XLOOKUP($A9,'01_Raw_Data'!$A$107:$A$148,'01_Raw_Data'!$H$107:$H$148) -> 70.120483 | P9: =_xlfn.XLOOKUP($A9,'01_Raw_Data'!$A$107:$A$148,'01_Raw_Data'!$I$107:$I$148) -> 71.097351 | Q9: =_xlfn.XLOOKUP($A9,'01_Raw_Data'!$A$107:$A$148,'01_Raw_Data'!$Q$107:$Q$148) -> 61.240841 | R9: =_xlfn.XLOOKUP($A9,'01_Raw_Data'!$A$107:$A$148,'01_Raw_Data'!$R$107:$R$148) -> 68.830956 | S9: =_xlfn.XLOOKUP($A9,'01_Raw_Data'!$A$107:$A$148,'01_Raw_Data'!$S$107:$S$148) -> 71.481956
A10: =_xlfn.XLOOKUP('01_Raw_Data'!$A15,'01_Raw_Data'!$A$7:$A$45, '01_Raw_Data'!$A$7:$A$45) -> Finland | B10: Yes | C10: =_xlfn.XLOOKUP('01_Raw_Data'!$A266, '01_Raw_Data'!$A$258:$A$296, '01_Raw_Data'!$D$258:$D$296) -> 50.634285 | D10: =_xlfn.XLOOKUP('01_Raw_Data'!$A315, '01_Raw_Data'!$A$307:$A$345,'01_Raw_Data'!$D$307:$D$345) -> 62.814381 | E10: =_xlfn.XLOOKUP('01_Raw_Data'!$A364, '01_Raw_Data'!$A$356:$A$394, '01_Raw_Data'!$D$356:$D$394) -> 54.787384 | F10: =_xlfn.XLOOKUP('01_Raw_Data'!$A116, '01_Raw_Data'!$A$108:$A$146, '01_Raw_Data'!$D$108:$D$146) -> 57.153187 | G10: =_xlfn.XLOOKUP('01_Raw_Data'!$A67,'01_Raw_Data'!$A$59:$A$97, '01_Raw_Data'!$B$59:$B$97) -> 45.7587 | H10: =RANK('01_Raw_Data'!$D116, '01_Raw_Data'!$D$108:$D$146, 0) -> 24 | I10: =_xlfn.XLOOKUP($A10,'01_Raw_Data'!$A$107:$A$148,'01_Raw_Data'!$B$107:$B$148) -> 63.487141 | J10: =_xlfn.XLOOKUP($A10,'01_Raw_Data'!$A$107:$A$148,'01_Raw_Data'!$C$107:$C$148) -> 65.648232 | K10: =_xlfn.XLOOKUP($A10,'01_Raw_Data'!$A$107:$A$148,'01_Raw_Data'!$D$107:$D$148) -> 57.153187 | L10: =_xlfn.XLOOKUP($A10,'01_Raw_Data'!$A$107:$A$148,'01_Raw_Data'!$E$107:$E$148) -> 64.769394 | M10: =_xlfn.XLOOKUP($A10,'01_Raw_Data'!$A$107:$A$148,'01_Raw_Data'!$F$107:$F$148) -> 66.253677 | N10: =_xlfn.XLOOKUP($A10,'01_Raw_Data'!$A$107:$A$148,'01_Raw_Data'!$G$107:$G$148) -> 52.121361 | O10: =_xlfn.XLOOKUP($A10,'01_Raw_Data'!$A$107:$A$148,'01_Raw_Data'!$H$107:$H$148) -> 61.253719 | P10: =_xlfn.XLOOKUP($A10,'01_Raw_Data'!$A$107:$A$148,'01_Raw_Data'!$I$107:$I$148) -> 69.452927 | Q10: =_xlfn.XLOOKUP($A10,'01_Raw_Data'!$A$107:$A$148,'01_Raw_Data'!$Q$107:$Q$148) -> 60.136684 | R10: =_xlfn.XLOOKUP($A10,'01_Raw_Data'!$A$107:$A$148,'01_Raw_Data'!$R$107:$R$148) -> 67.734756 | S10: =_xlfn.XLOOKUP($A10,'01_Raw_Data'!$A$107:$A$148,'01_Raw_Data'!$S$107:$S$148) -> 70.893532
A11: =_xlfn.XLOOKUP('01_Raw_Data'!$A16,'01_Raw_Data'!$A$7:$A$45, '01_Raw_Data'!$A$7:$A$45) -> France | B11: Yes | C11: =_xlfn.XLOOKUP('01_Raw_Data'!$A267, '01_Raw_Data'!$A$258:$A$296, '01_Raw_Data'!$D$258:$D$296) -> 57.035603 | D11: =_xlfn.XLOOKUP('01_Raw_Data'!$A316, '01_Raw_Data'!$A$307:$A$345,'01_Raw_Data'!$D$307:$D$345) -> 60.677387 | E11: =_xlfn.XLOOKUP('01_Raw_Data'!$A365, '01_Raw_Data'!$A$356:$A$394, '01_Raw_Data'!$D$356:$D$394) -> 53.907524 | F11: =_xlfn.XLOOKUP('01_Raw_Data'!$A117, '01_Raw_Data'!$A$108:$A$146, '01_Raw_Data'!$D$108:$D$146) -> 58.04879 | G11: =_xlfn.XLOOKUP('01_Raw_Data'!$A68,'01_Raw_Data'!$A$59:$A$97, '01_Raw_Data'!$B$59:$B$97) -> 38.732949 | H11: =RANK('01_Raw_Data'!$D117, '01_Raw_Data'!$D$108:$D$146, 0) -> 21 | I11: =_xlfn.XLOOKUP($A11,'01_Raw_Data'!$A$107:$A$148,'01_Raw_Data'!$B$107:$B$148) -> 61.311966 | J11: =_xlfn.XLOOKUP($A11,'01_Raw_Data'!$A$107:$A$148,'01_Raw_Data'!$C$107:$C$148) -> 62.849388 | K11: =_xlfn.XLOOKUP($A11,'01_Raw_Data'!$A$107:$A$148,'01_Raw_Data'!$D$107:$D$148) -> 58.04879 | L11: =_xlfn.XLOOKUP($A11,'01_Raw_Data'!$A$107:$A$148,'01_Raw_Data'!$E$107:$E$148) -> 60.445614 | M11: =_xlfn.XLOOKUP($A11,'01_Raw_Data'!$A$107:$A$148,'01_Raw_Data'!$F$107:$F$148) -> 66.252151 | N11: =_xlfn.XLOOKUP($A11,'01_Raw_Data'!$A$107:$A$148,'01_Raw_Data'!$G$107:$G$148) -> 55.019676 | O11: =_xlfn.XLOOKUP($A11,'01_Raw_Data'!$A$107:$A$148,'01_Raw_Data'!$H$107:$H$148) -> 62.542728 | P11: =_xlfn.XLOOKUP($A11,'01_Raw_Data'!$A$107:$A$148,'01_Raw_Data'!$I$107:$I$148) -> 69.182228 | Q11: =_xlfn.XLOOKUP($A11,'01_Raw_Data'!$A$107:$A$148,'01_Raw_Data'!$Q$107:$Q$148) -> 58.349739 | R11: =_xlfn.XLOOKUP($A11,'01_Raw_Data'!$A$107:$A$148,'01_Raw_Data'!$R$107:$R$148) -> 67.273293 | S11: =_xlfn.XLOOKUP($A11,'01_Raw_Data'!$A$107:$A$148,'01_Raw_Data'!$S$107:$S$148) -> 66.587189
A12: =_xlfn.XLOOKUP('01_Raw_Data'!$A17,'01_Raw_Data'!$A$7:$A$45, '01_Raw_Data'!$A$7:$A$45) -> Germany | B12: Yes | C12: =_xlfn.XLOOKUP('01_Raw_Data'!$A268, '01_Raw_Data'!$A$258:$A$296, '01_Raw_Data'!$D$258:$D$296) -> 81.344879 | D12: =_xlfn.XLOOKUP('01_Raw_Data'!$A317, '01_Raw_Data'!$A$307:$A$345,'01_Raw_Data'!$D$307:$D$345) -> 75.017296 | E12: =_xlfn.XLOOKUP('01_Raw_Data'!$A366, '01_Raw_Data'!$A$356:$A$394, '01_Raw_Data'!$D$356:$D$394) -> 63.386528 | F12: =_xlfn.XLOOKUP('01_Raw_Data'!$A118, '01_Raw_Data'!$A$108:$A$146, '01_Raw_Data'!$D$108:$D$146) -> 74.905792 | G12: =_xlfn.XLOOKUP('01_Raw_Data'!$A69,'01_Raw_Data'!$A$59:$A$97, '01_Raw_Data'!$B$59:$B$97) -> 75.478607 | H12: =RANK('01_Raw_Data'!$D118, '01_Raw_Data'!$D$108:$D$146, 0) -> 1 | I12: =_xlfn.XLOOKUP($A12,'01_Raw_Data'!$A$107:$A$148,'01_Raw_Data'!$B$107:$B$148) -> 74.683891 | J12: =_xlfn.XLOOKUP($A12,'01_Raw_Data'!$A$107:$A$148,'01_Raw_Data'!$C$107:$C$148) -> 77.260445 | K12: =_xlfn.XLOOKUP($A12,'01_Raw_Data'!$A$107:$A$148,'01_Raw_Data'!$D$107:$D$148) -> 74.905792 | L12: =_xlfn.XLOOKUP($A12,'01_Raw_Data'!$A$107:$A$148,'01_Raw_Data'!$E$107:$E$148) -> 77.171936 | M12: =_xlfn.XLOOKUP($A12,'01_Raw_Data'!$A$107:$A$148,'01_Raw_Data'!$F$107:$F$148) -> 74.356583 | N12: =_xlfn.XLOOKUP($A12,'01_Raw_Data'!$A$107:$A$148,'01_Raw_Data'!$G$107:$G$148) -> 69.254059 | O12: =_xlfn.XLOOKUP($A12,'01_Raw_Data'!$A$107:$A$148,'01_Raw_Data'!$H$107:$H$148) -> 76.591637 | P12: =_xlfn.XLOOKUP($A12,'01_Raw_Data'!$A$107:$A$148,'01_Raw_Data'!$I$107:$I$148) -> 79.59671 | Q12: =_xlfn.XLOOKUP($A12,'01_Raw_Data'!$A$107:$A$148,'01_Raw_Data'!$Q$107:$Q$148) -> 68.270805 | R12: =_xlfn.XLOOKUP($A12,'01_Raw_Data'!$A$107:$A$148,'01_Raw_Data'!$R$107:$R$148) -> 75.542641 | S12: =_xlfn.XLOOKUP($A12,'01_Raw_Data'!$A$107:$A$148,'01_Raw_Data'!$S$107:$S$148) -> 79.945038
A13: =_xlfn.XLOOKUP('01_Raw_Data'!$A18,'01_Raw_Data'!$A$7:$A$45, '01_Raw_Data'!$A$7:$A$45) -> Greece | B13: Yes | C13: =_xlfn.XLOOKUP('01_Raw_Data'!$A269, '01_Raw_Data'!$A$258:$A$296, '01_Raw_Data'!$D$258:$D$296) -> 71.145958 | D13: =_xlfn.XLOOKUP('01_Raw_Data'!$A318, '01_Raw_Data'!$A$307:$A$345,'01_Raw_Data'!$D$307:$D$345) -> 69.068871 | E13: =_xlfn.XLOOKUP('01_Raw_Data'!$A367, '01_Raw_Data'!$A$356:$A$394, '01_Raw_Data'!$D$356:$D$394) -> 49.871536 | F13: =_xlfn.XLOOKUP('01_Raw_Data'!$A119, '01_Raw_Data'!$A$108:$A$146, '01_Raw_Data'!$D$108:$D$146) -> 65.956383 | G13: =_xlfn.XLOOKUP('01_Raw_Data'!$A70,'01_Raw_Data'!$A$59:$A$97, '01_Raw_Data'!$B$59:$B$97) -> 32.095543 | H13: =RANK('01_Raw_Data'!$D119, '01_Raw_Data'!$D$108:$D$146, 0) -> 7 | I13: =_xlfn.XLOOKUP($A13,'01_Raw_Data'!$A$107:$A$148,'01_Raw_Data'!$B$107:$B$148) -> 57.735909 | J13: =_xlfn.XLOOKUP($A13,'01_Raw_Data'!$A$107:$A$148,'01_Raw_Data'!$C$107:$C$148) -> 65.13932 | K13: =_xlfn.XLOOKUP($A13,'01_Raw_Data'!$A$107:$A$148,'01_Raw_Data'!$D$107:$D$148) -> 65.956383 | L13: =_xlfn.XLOOKUP($A13,'01_Raw_Data'!$A$107:$A$148,'01_Raw_Data'!$E$107:$E$148) -> 62.855473 | M13: =_xlfn.XLOOKUP($A13,'01_Raw_Data'!$A$107:$A$148,'01_Raw_Data'!$F$107:$F$148) -> 56.419125 | N13: =_xlfn.XLOOKUP($A13,'01_Raw_Data'!$A$107:$A$148,'01_Raw_Data'!$G$107:$G$148) -> 55.393612 | O13: =_xlfn.XLOOKUP($A13,'01_Raw_Data'!$A$107:$A$148,'01_Raw_Data'!$H$107:$H$148) -> 64.306335 | P13: =_xlfn.XLOOKUP($A13,'01_Raw_Data'!$A$107:$A$148,'01_Raw_Data'!$I$107:$I$148) -> 67.878708 | Q13: =_xlfn.XLOOKUP($A13,'01_Raw_Data'!$A$107:$A$148,'01_Raw_Data'!$Q$107:$Q$148) -> 53.387024 | R13: =_xlfn.XLOOKUP($A13,'01_Raw_Data'!$A$107:$A$148,'01_Raw_Data'!$R$107:$R$148) -> 59.700157 | S13: =_xlfn.XLOOKUP($A13,'01_Raw_Data'!$A$107:$A$148,'01_Raw_Data'!$S$107:$S$148) -> 65.728882
... A40: =_xlfn.XLOOKUP('01_Raw_Data'!$A45,'01_Raw_Data'!$A$7:$A$45, '01_Raw_Data'!$A$7:$A$45) -> Yemen | B40: No | C40: =_xlfn.XLOOKUP('01_Raw_Data'!$A296, '01_Raw_Data'!$A$258:$A$296, '01_Raw_Data'!$D$258:$D$296) -> 51.112564 | D40: =_xlfn.XLOOKUP('01_Raw_Data'!$A345, '01_Raw_Data'!$A$307:$A$345,'01_Raw_Data'!$D$307:$D$345) -> 42.826057 | E40: =_xlfn.XLOOKUP('01_Raw_Data'!$A394, '01_Raw_Data'!$A$356:$A$394, '01_Raw_Data'!$D$356:$D$394) -> 32.308781 | F40: =_xlfn.XLOOKUP('01_Raw_Data'!$A146, '01_Raw_Data'!$A$108:$A$146, '01_Raw_Data'!$D$108:$D$146) -> 43.622879 | G40: =_xlfn.XLOOKUP('01_Raw_Data'!$A97,'01_Raw_Data'!$A$59:$A$97, '01_Raw_Data'!$B$59:$B$97) -> 2.9547995 | H40: =RANK('01_Raw_Data'!$D146, '01_Raw_Data'!$D$108:$D$146, 0) -> 39 | I40: =_xlfn.XLOOKUP($A40,'01_Raw_Data'!$A$107:$A$148,'01_Raw_Data'!$B$107:$B$148) -> 40.992931 | J40: =_xlfn.XLOOKUP($A40,'01_Raw_Data'!$A$107:$A$148,'01_Raw_Data'!$C$107:$C$148) -> 44.091385 | K40: =_xlfn.XLOOKUP($A40,'01_Raw_Data'!$A$107:$A$148,'01_Raw_Data'!$D$107:$D$148) -> 43.622879 | L40: =_xlfn.XLOOKUP($A40,'01_Raw_Data'!$A$107:$A$148,'01_Raw_Data'!$E$107:$E$148) -> 42.515732 | M40: =_xlfn.XLOOKUP($A40,'01_Raw_Data'!$A$107:$A$148,'01_Raw_Data'!$F$107:$F$148) -> 35.860771 | N40: =_xlfn.XLOOKUP($A40,'01_Raw_Data'!$A$107:$A$148,'01_Raw_Data'!$G$107:$G$148) -> 38.951725 | O40: =_xlfn.XLOOKUP($A40,'01_Raw_Data'!$A$107:$A$148,'01_Raw_Data'!$H$107:$H$148) -> 45.062019 | P40: =_xlfn.XLOOKUP($A40,'01_Raw_Data'!$A$107:$A$148,'01_Raw_Data'!$I$107:$I$148) -> 52.678902 | Q40: =_xlfn.XLOOKUP($A40,'01_Raw_Data'!$A$107:$A$148,'01_Raw_Data'!$Q$107:$Q$148) -> 40.263309 | R40: =_xlfn.XLOOKUP($A40,'01_Raw_Data'!$A$107:$A$148,'01_Raw_Data'!$R$107:$R$148) -> 44.389889 | S40: =_xlfn.XLOOKUP($A40,'01_Raw_Data'!$A$107:$A$148,'01_Raw_Data'!$S$107:$S$148) -> 51.340847

Sheet 06_Pivot_Tables
A1: Country | B1: Overall_Score_Out_Of_100 | C1: Overall_Rank_Out_Of_39
A2: Germany | B2: 74.905792 | C2: 1
A3: Thailand | B3: 74.159775 | C3: 2
A4: Ireland | B4: 69.667519 | C4: 3
A5: Estonia | B5: 68.8592 | C5: 4
A6: Hong Kong (China) | B6: 66.87442 | C6: 5
A7: Korea | B7: 66.567192 | C7: 6
A8: Greece | B8: 65.956383 | C8: 7
A9: Mexico | B9: 64.924568 | C9: 8
A10: Malta | B10: 64.890106 | C10: 9
A11: Brazil | B11: 64.383331 | C11: 10
A12: Spain | B12: 62.647133 | C12: 11
A13: Netherlands | B13: 60.913193 | C13: 12
... A40: Yemen | B40: 43.622879 | C40: 39
A43: OECD_Member (Yes/No) | B43: Overall_Score_Out_Of_100 | C43: Knowledge_Out_Of_100 | D43: Behaviour_Out_Of_100 | E43: Attitudes_Out_Of_100
A44: Yes | B44: 60.048737 | C44: 63.076388 | D44: 60.023478 | E44: 54.757837
A45: No | B45: 58.123633 | C45: 58.47826 | D45: 60.265098 | E45: 52.589404
A48: Metric | B48: Ireland | C48: OECD_Average | D48: Overall_Average
A49: Knowledge | B49: ='04_Analysis'!B2 -> 68.970192 | C49: ='01_Raw_Data'!D298 -> 62.707148 | D49: ='01_Raw_Data'!D297 -> 60.954175
A50: Behaviour | B50: ='04_Analysis'!B3 -> 75.686768 | C50: ='01_Raw_Data'!D347 -> 60.143175 | D50: ='01_Raw_Data'!D346 -> 60.134995
A51: Attitudes | B51: ='04_Analysis'!B4 -> 57.344543 | C51: ='01_Raw_Data'!D396 -> 54.943612 | D51: ='01_Raw_Data'!D395 -> 53.757022
A54: Ireland_Score | B54: OECD Youth Average | C54: Ireland Advantage | D54: Youth Penalty | E54: Lowest Dimension | F54: Behaviour Advantage | G54: Attitude Advantage | H54: Knowledge Share | I54: Improvement Needed | J54: Performance Indicator
A55: 69.667519 | B55: 60.048737 | C55: 9.6187819 | D55: 2.0102997 | E55: 57.344543 | F55: 6.7165756 | G55: -11.625648 | H55: 0.98999065 | I55: 0 | J55: Above OECD

Sheet 07_Dashboard
B1: Financial Literacy Among Young Irish Adults (18-29)
B6: Overall Literacy Score | G6: Global Rank | L6: Ireland vs OECD Gap | Q6: Youth Penalty (vs ages 30-59)
B8: =GETPIVOTDATA("[Measures].[Ireland_Score]",'06_Pivot_Tables'!$A$54) -> 69.667519 | G8: ='04_Analysis'!B9 & "rd of 39" -> 3rd of 39 | L8: =GETPIVOTDATA("[Measures].[Ireland Advantage]",'06_Pivot_Tables'!$A$54) -> 9.6187819 | Q8: =GETPIVOTDATA("[Measures].[Youth Penalty]",'06_Pivot_Tables'!$A$54) -> 2.0102997

Sheet 08_Insights
A1: Question | B1: Finding | C1: Behavioural Explanation | D1: Recommendation
A2: Why do Irish 18-29 year olds score below older age groups? | B2: Irish adults aged 18-29 score 68.01 – 3.29 points below the 30-59 cohort (71.30), suggesting financial literacy builds with age and life experience rather than being established in youth. | C2: Present bias causes young people to prioritise immediate spending over building long-term financial habits. Financial literacy compounds with experience and age, not with education alone. | D2: A life-stage-based financial literacy app that triggers education at the moment of financial events (first payslip, SUSI application, first job) can accelerate the learning curve that currently only comes with age.
A3: Which financial knowledge areas are weakest in Ireland? | B3: Compound interest is poorly understood with less than half of Irish adults (45%) correctly calculating it. | C3: Compound interest is an abstract concept with no immediate visible consequence. Hyperbolic discounting means people heavily discount future returns, reducing motivation to engage with compound growth concepts. The complexity gap between understanding inflation (concrete, daily) and compound interest (abstract, long-term) reflects temporal distance bias. | D3: An interactive compound interest visualiser that shows the real-time impact of starting to save at 20 vs 30 vs 40 makes the abstract concrete and activates loss aversion (the cost of delay).
A4: Does income influence financial literacy in Ireland? | B4: Low-income Irish adults score lowest at 64 – 11 points lower than high-income adults | C4: Financial stress reduces cognitive bandwidth – lower-income individuals allocate mental resources to immediate financial survival, leaving less capacity for long-term financial planning. | D4: Core educational content must be free. Monetisation through premium features ensures the product remains accessible to those who need it most – low and medium income earners who show the largest potential literacy gain.
A5: Why does Ireland perform well on behaviour but poorly on attitudes? | B5: Ireland's attitudes score lags behind behaviour by 14 points | C5: Status quo bias and optimism bias mean Irish adults manage their day-to-day finances adequately but resist making long-term changes or confronting uncomfortable financial realities. The "I'll start saving for a pension next year" effect is a classic manifestation of present bias combined with optimistic overconfidence about future behaviour. | D5: Future financial goals must be made vivid and specific. Research shows that mental simulation of specific future scenarios (visualising yourself at 65 with or without a pension) significantly improves financial planning behaviour.
